<?xml version="1.0" encoding="utf-8"?>
<!-- This URDF was automatically created by SolidWorks to URDF Exporter! Originally created by Stephen Brawner (brawner@gmail.com) 
     Commit Version:   Build Version: 1.6.9102.25287
     For more information, please see http://wiki.ros.org/sw_urdf_exporter -->
<robot
  name="HARIMOTO">
  <link
    name="base_link">
    <inertial>
      <origin
        xyz="0.287280488181305 0.119758135093113 0.0120759441708456"
        rpy="0 0 0" />
      <mass
        value="0.0468580060932661" />
      <inertia
        ixx="1.56534574192188E-05"
        ixy="6.61087369064978E-07"
        ixz="-7.21642700260538E-07"
        iyy="1.29229800207445E-05"
        iyz="5.02340603686712E-06"
        izz="1.41194963510472E-05" />
    </inertial>
    <visual>
      <origin
        xyz="0 0 0"
        rpy="0 0 0" />
      <geometry>
        <mesh
          filename="package://HARIMOTO/meshes/base_link.STL" />
      </geometry>
      <material
        name="">
        <color
          rgba="1 1 1 1" />
      </material>
    </visual>
    <collision>
      <origin
        xyz="0 0 0"
        rpy="0 0 0" />
      <geometry>
        <mesh
          filename="package://HARIMOTO/meshes/base_link.STL" />
      </geometry>
    </collision>
  </link>
  <link
    name="upper_shoulder">
    <inertial>
      <origin
        xyz="0.0129549305137395 -0.0148664141809147 -0.0276892742587568"
        rpy="0 0 0" />
      <mass
        value="0.0335476434855063" />
      <inertia
        ixx="3.81490155615431E-06"
        ixy="1.21543917806919E-08"
        ixz="2.11998108883285E-08"
        iyy="4.6464870940964E-06"
        iyz="9.45842330050842E-09"
        izz="3.45395092938991E-06" />
    </inertial>
    <visual>
      <origin
        xyz="0 0 0"
        rpy="0 0 0" />
      <geometry>
        <mesh
          filename="package://HARIMOTO/meshes/upper_shoulder.STL" />
      </geometry>
      <material
        name="">
        <color
          rgba="0.298039215686275 0.298039215686275 0.298039215686275 1" />
      </material>
    </visual>
    <collision>
      <origin
        xyz="0 0 0"
        rpy="0 0 0" />
      <geometry>
        <mesh
          filename="package://HARIMOTO/meshes/upper_shoulder.STL" />
      </geometry>
    </collision>
  </link>
  <joint
    name="upper_shoulder"
    type="revolute">
    <origin
      xyz="0.27658 -0.037897 0.095074"
      rpy="0.18413 0.71623 2.0474" />
    <parent
      link="base_link" />
    <child
      link="upper_shoulder" />
    <axis
      xyz="0 0 1" />
    <limit
      lower="-1.2"
      upper="0"
      effort="0"
      velocity="10" />
  </joint>
  <link
    name="lower_shoulder">
    <inertial>
      <origin
        xyz="-6.29007393652611E-05 -0.0773879745241495 -2.62161943492822E-05"
        rpy="0 0 0" />
      <mass
        value="0.0576719241727568" />
      <inertia
        ixx="1.71209095381949E-05"
        ixy="9.45797260721556E-09"
        ixz="-1.21542702244489E-08"
        iyy="4.45012358965739E-06"
        iyz="-2.11998275069939E-08"
        izz="1.64179743238391E-05" />
    </inertial>
    <visual>
      <origin
        xyz="0 0 0"
        rpy="0 0 0" />
      <geometry>
        <mesh
          filename="package://HARIMOTO/meshes/lower_shoulder.STL" />
      </geometry>
      <material
        name="">
        <color
          rgba="0.298039215686275 0.298039215686275 0.298039215686275 1" />
      </material>
    </visual>
    <collision>
      <origin
        xyz="0 0 0"
        rpy="0 0 0" />
      <geometry>
        <mesh
          filename="package://HARIMOTO/meshes/lower_shoulder.STL" />
      </geometry>
    </collision>
  </link>
  <joint
    name="lower_shoulder"
    type="revolute">
    <origin
      xyz="-0.005 -0.0145 -0.041"
      rpy="1.5708 -1.5708 0" />
    <parent
      link="upper_shoulder" />
    <child
      link="lower_shoulder" />
    <axis
      xyz="0 1 0" />
    <limit
      lower="-2.7"
      upper="0.75"
      effort="0"
      velocity="10" />
  </joint>
  <link
    name="upper_arm">
    <inertial>
      <origin
        xyz="-0.00733809185080697 9.50609948116854E-05 -0.00741154132403015"
        rpy="0 0 0" />
      <mass
        value="0.0214573443165031" />
      <inertia
        ixx="2.31688951311032E-06"
        ixy="3.18660578583501E-09"
        ixz="2.10545109019358E-08"
        iyy="3.0075651917683E-06"
        iyz="1.16767658606974E-08"
        izz="2.83620449126694E-06" />
    </inertial>
    <visual>
      <origin
        xyz="0 0 0"
        rpy="0 0 0" />
      <geometry>
        <mesh
          filename="package://HARIMOTO/meshes/upper_arm.STL" />
      </geometry>
      <material
        name="">
        <color
          rgba="0.298039215686275 0.298039215686275 0.298039215686275 1" />
      </material>
    </visual>
    <collision>
      <origin
        xyz="0 0 0"
        rpy="0 0 0" />
      <geometry>
        <mesh
          filename="package://HARIMOTO/meshes/upper_arm.STL" />
      </geometry>
    </collision>
  </link>
  <joint
    name="upper_arm"
    type="revolute">
    <origin
      xyz="-0.0275 -0.124 0"
      rpy="-1.5708 0 -1.5708" />
    <parent
      link="lower_shoulder" />
    <child
      link="upper_arm" />
    <axis
      xyz="0 -1 0" />
    <limit
      lower="-0.7"
      upper="0.7"
      effort="0"
      velocity="10" />
  </joint>
  <link
    name="lower_arm">
    <inertial>
      <origin
        xyz="0.0421277473518189 0.0165474898549971 0.0165286055871077"
        rpy="0 0 0" />
      <mass
        value="0.0477129093267453" />
      <inertia
        ixx="5.58515262715872E-06"
        ixy="-4.38333157894734E-10"
        ixz="9.16849548962552E-07"
        iyy="2.10134302800355E-05"
        iyz="1.25446647580095E-09"
        izz="1.79446863505717E-05" />
    </inertial>
    <visual>
      <origin
        xyz="0 0 0"
        rpy="0 0 0" />
      <geometry>
        <mesh
          filename="package://HARIMOTO/meshes/lower_arm.STL" />
      </geometry>
      <material
        name="">
        <color
          rgba="0.792156862745098 0.819607843137255 0.933333333333333 1" />
      </material>
    </visual>
    <collision>
      <origin
        xyz="0 0 0"
        rpy="0 0 0" />
      <geometry>
        <mesh
          filename="package://HARIMOTO/meshes/lower_arm.STL" />
      </geometry>
    </collision>
  </link>
  <joint
    name="lower_arm"
    type="revolute">
    <origin
      xyz="0.1085 0.0166 0.0151"
      rpy="0 0 3.1416" />
    <parent
      link="upper_arm" />
    <child
      link="lower_arm" />
    <axis
      xyz="0 0 -1" />
    <limit
      lower="-1.5"
      upper="1.5"
      effort="0"
      velocity="10" />
  </joint>
</robot>